<robot name="robot_model">
  <!-- Base link -->
  <link name="base_link">
    <visual>
      <geometry>
        <box size="0.2 0.2 0.1"/>
      </geometry>
    </visual>
  </link>

  <!-- Joint and links: 10 links -->
  <joint name="joint_1" type="revolute">
    <parent link="base_link"/>
    <child link="link_1"/>
    <origin xyz="0 0 0.05" rpy="0 0 0"/>
    <axis xyz="0 0 1"/>
    <limit effort="10.0" lower="-1.5" upper="1.5" velocity="1.0"/>
  </joint>
  <link name="link_1">
    <visual>
      <geometry>
        <cylinder length="0.2" radius="0.05"/>
      </geometry>
    </visual>
  </link>

  <joint name="joint_2" type="revolute">
    <parent link="link_1"/>
    <child link="link_2"/>
    <origin xyz="0 0 0.2" rpy="0 0 0"/>
    <axis xyz="0 1 0"/>
    <limit effort="10.0" lower="-1.5" upper="1.5" velocity="1.0"/>
  </joint>
  <link name="link_2">
    <visual>
      <geometry>
        <cylinder length="0.2" radius="0.05"/>
      </geometry>
    </visual>
  </link>

  <joint name="joint_3" type="prismatic">
    <parent link="link_2"/>
    <child link="link_3"/>
    <origin xyz="0 0 0.2" rpy="0 0 0"/>
    <axis xyz="0 0 1"/>
    <limit effort="10.0" lower="0.0" upper="0.1" velocity="0.5"/>
  </joint>
  <link name="link_3">
    <visual>
      <geometry>
        <box size="0.1 0.1 0.2"/>
      </geometry>
    </visual>
  </link>

  <joint name="joint_4" type="revolute">
    <parent link="link_3"/>
    <child link="link_4"/>
    <origin xyz="0 0 0.2" rpy="0 0 0"/>
    <axis xyz="0 1 0"/>
    <limit effort="10.0" lower="-1.5" upper="1.5" velocity="1.0"/>
  </joint>
  <link name="link_4">
    <visual>
      <geometry>
        <cylinder length="0.2" radius="0.05"/>
      </geometry>
    </visual>
  </link>

  <joint name="joint_5" type="revolute">
    <parent link="link_4"/>
    <child link="link_5"/>
    <origin xyz="0 0 0.2" rpy="0 0 0"/>
    <axis xyz="0 0 1"/>
    <limit effort="10.0" lower="-1.5" upper="1.5" velocity="1.0"/>
  </joint>
  <link name="link_5">
    <visual>
      <geometry>
        <box size="0.1 0.1 0.2"/>
      </geometry>
    </visual>
  </link>

  <!-- Fixed joints: link_6 to link_10 -->
  <joint name="joint_6" type="fixed">
    <parent link="link_5"/>
    <child link="link_6"/>
    <origin xyz="0 0 0.2" rpy="0 0 0"/>
  </joint>
  <link name="link_6">
    <visual>
      <geometry>
        <box size="0.1 0.1 0.1"/>
      </geometry>
    </visual>
  </link>

  <joint name="joint_7" type="fixed">
    <parent link="link_6"/>
    <child link="link_7"/>
    <origin xyz="0 0 0.1" rpy="0 0 0"/>
  </joint>
  <link name="link_7">
    <visual>
      <geometry>
        <box size="0.1 0.1 0.1"/>
      </geometry>
    </visual>
  </link>

  <joint name="joint_8" type="fixed">
    <parent link="link_7"/>
    <child link="link_8"/>
    <origin xyz="0 0 0.1" rpy="0 0 0"/>
  </joint>
  <link name="link_8">
    <visual>
      <geometry>
        <box size="0.1 0.1 0.1"/>
      </geometry>
    </visual>
  </link>

  <joint name="joint_9" type="fixed">
    <parent link="link_8"/>
    <child link="link_9"/>
    <origin xyz="0 0 0.1" rpy="0 0 0"/>
  </joint>
  <link name="link_9">
    <visual>
      <geometry>
        <box size="0.1 0.1 0.1"/>
      </geometry>
    </visual>
  </link>

  <joint name="joint_10" type="fixed">
    <parent link="link_9"/>
    <child link="link_10"/>
    <origin xyz="0 0 0.1" rpy="0 0 0"/>
  </joint>
  <link name="link_10">
    <visual>
      <geometry>
        <box size="0.1 0.1 0.1"/>
      </geometry>
    </visual>
  </link>
</robot>
